Workbook

Sheet Self-Assessment
A1: EQuiPD | B1: short_q | C1: Question | D1: Response | E1: Notes | H1: DS | I1: CB | J1: PS | K1: IM | L1: AP | M1: SE | N1: TC | O1: DI | P1: IP | Q1: PE | R1: DE | S1: SO | T1: AI
A2: v260116
C3: EQuiPD: Equity in Air Quality Policy & Data Ecosystem
C4: Self-Assessment Tool
C6: Overview
C7: The Equity in Air Quality Policy and Data Ecosystem self-assessment (EQuiPD) tool will help you understand your city’s ability to effectively manage, use, craft, and implement policies at the intersection of air quality and equity - informed by air quality, health and equity data. EQuiPD is designed to guide your development around data, air quality monitoring, technical capacity, training, and infrastructure so that you can address air quality with full consideration of health and equity. You can use EQuiPD-generated results to ensure you have the necessary data for a more complete understanding of your city and determine if you have fundamental information necessary for designing equitable air quality policies and assessing policy benefits aligned with the five equity impact areas outlined in the C40 report: Clean air, healthy and thriving communities: Opportunities for city leadership [1]. Finally, EQuiPD will guide you in identifying gaps across your city’s equity in air quality policy ecosystem so you can focus development and strengthen the underlying data resources, technical capacities to manage and process data, and partnerships for sharing and integrating air quality, health and equity data that can compliment your city’s efforts to ensure more equitable policy outcomes.
C8: [1] Clean air, healthy and thriving communities: Opportunities for city leadership
C10: How to use the self-assessment tool
C11: The EQuiPD self-assessment contains 80 questions regarding data in our city. These questions are broken down across how data is collected, linked, disaggregated and integrated, analyzed, and communicated. Your responses to these questions will be used to calculate scores across six categories within four ecosystem domains and three themes of equity (see [2] for more detail). As you make progress in developing your city's data ecosystem for equitable air quality policies, you are encouraged to redo this assessment again in the future and reflect on growth over time. **Note: Questions marked '*' are essential to answer and should not be skipped. Other questions will help add nuance for EQuiPD to understand your city's policy and data ecosystem and are highly recommended to answer.
C12: Self-scoring is necessary as you have the best knowledge of your own city’s capacities. The scoring scale for all questions is described as follows. You may assign fractional scores (e.g., 2.5) if you fall between two scores.
C13: 0 No implementation or unknown.
C14: 1 Limited implementation. Pilot work is underway related to some aspects of this question, but it is not sustainable or will not provide long-term actionable insights.
C15: 2 Partial implementation. There is operational work related to this question that is ongoing but may be limited in terms of equity integration (e.g., it has not reached marginalized neighborhoods or cannot fully quantify or address potential disparities).
C16: 3 Full implementation. Long-term, sustainable, and transparent ability to address this question. Equity is given full consideration with disaggregation (when applicable) across multiple characterizations (i.e., demographic, socioeconomic).
... C21: Self-Assessment Questions
C22: Preliminary | D22: Answers
B23: City | C23: City name? (Use dropdown list to select from C40 cities, or enter 'Not listed') | D23: United Arab Emirates - Dubai
B24: Other_city | C24: Other city (write here, formatted as "Country - City")
B25: Name | C25: Name of person filling out this self-assessment?
B26: Date | C26: Date completed | D26: 11/26/2025
B27: Share | C27: Are you willing to share your results with other C40 cities? (Yes/No) | D27: Yes
H28: Categories | N28: Domains | R28: Themes
B29: 0 | C29: Data Collection (Health, Air Quality, Demographics, Socioeconomics) | D29: Score (0-3) | E29: Notes | H29: DS | I29: CB | J29: PS | K29: IM | L29: AP | M29: SE | N29: TC | O29: DI | P29: IP | Q29: PE | R29: DE | S29: SO | T29: AI
B30: =B29+1 -> 1 | C30: *Do air pollution monitoring locations prioritize high-risk groups (for example., children, elderly, people with pre-existing conditions) and neighborhoods with historical underinvestment? | D30: 1 | L30: 1 | P30: 1 | R30: 1
B31: =B30+1 -> 2 | C31: Are community members from marginalized or vulnerable groups–or from disproportionately exposed areas of your city–engaged in decisionmaking about where to locate air pollution monitors? Marginalized community members may include low-income residents, racial or ethnic minority groups, migrants, linguistic minorities, religious minorities, Indigenous peoples, women, or any other oppressed or disenfranchised group. | D31: 1 | H31: 1 | L31: 1 | Q31: 1 | T31: 1
B32: =B31+1 -> 3 | C32: Are labor unions, worker cooperatives, and community organizations actively engaged in decisionmaking about where to locate air pollution monitors? Spatial and temporal resolution should be high enough to identify specific neighborhoods and other areas of your city that are disproportionately impacted by air pollution. | D32: 1 | H32: 1 | L32: 1 | M32: 1 | Q32: 1 | S32: 1 | T32: 1
B33: =B32+1 -> 4 | C33: *Does your city collect air pollution data at high spatial and temporal resolution, especially in areas of concern and prioritize high risk groups (e.g., children, elderly, underinvested neighborhoods)? Spatial and temporal resolution should be high enough to identify specific neighborhoods and other areas of your city that are disproportionately impacted by air pollution. | D33: 1.5 | L33: 1 | N33: 1 | R33: 1
B34: =B33+1 -> 5 | C34: *Does your city collect air pollution data from point, area, and mobile sources, including power plants, shipping lanes, transportation hubs and routes, and industrial areas? | D34: 3 | M34: 1 | N34: 1 | R34: 1 | S34: 1
B35: =B34+1 -> 6 | C35: Are smaller, un-inventoried, unconventional, hyper-local, or illegal sources of air pollution tracked by your city, preferably in consultation with vulnerable communities? Such sources may include backyard burning or unlicensed chemical use. | D35: 1 | H35: 1 | J35: 1 | M35: 1 | O35: 1 | P35: 1 | Q35: 1 | R35: 1 | S35: 1
B36: =B35+1 -> 7 | C36: *Does your city collect detailed social, demographic, and economic data about its residents and where they live? These datasets might include resident age, sex and gender, income, migration status, county of origin, racial or ethnic identity, religious affiliation, primary language spoken, education level, employment status, and occupation. They might also include area-level variables like poverty rates or joblessness rates. This data is critical to understanding the sociodemographic composition of neighborhoods and how some groups might be affected by air pollution and air quality policies more than others. | D36: 1 | H36: 1 | J36: 1 | N36: 1 | P36: 1 | S36: 1 | T36: 1
B37: =B36+1 -> 8 | C37: Does your city government have partnerships with industry, transportation, and agricultural sectors to improve emission inventories? | D37: 3 | M37: 1 | Q37: 1 | S37: 1
B38: =B37+1 -> 9 | C38: *Is data collected regarding the type of energy sources (coal, oil, gas, renewables, etc.) used by households in your city, as well as the location and number of such households? For example, do you know the location and number of households that have access to “clean energy,” which includes energy sources that produce no greenhouse gas emissions during their production or use? | D38: 1 | H38: 1 | N38: 1 | S38: 1
B39: =B38+1 -> 10 | C39: Does your city have the ability (sensors, expertise, etc) to gather indoor air quality data across diverse housing types and locations (e.g., underinvested neighborhoods, high-rise apartments)? | D39: 1 | L39: 1 | N39: 1 | T39: 1
B40: =B39+1 -> 11 | C40: Does your city collect data on indoor air quality proxy measures? “Proxy measures” include any data points that indicate potential indoor air quality problems. For example, mold complaints or mold abatement requests can indicate homes with poor indoor air quality. | D40: 0 | L40: 1 | N40: 1 | T40: 1
B41: =B40+1 -> 12 | C41: *Does your city collect or have access to real-time meteorological forecast data for your city and the surrounding areas? Meteorological data can be important both for air quality monitoring and for alerting residents to potential health hazards. Such data is particularly important for cities that experience extreme weather events. | D41: 3 | L41: 1 | N41: 1 | R41: 1
B42: =B41+1 -> 13 | C42: *Does your city collect data on accessibility that can characterize inequities for specific vulnerable populations, such as low-income or elderly populations? For this question, “accessibility” refers to whether all city residents–regardless of their physical or intellectual abilities–can interact with the information on air quality and related issues that you provide. | D42: 0 | J42: 1 | O42: 1 | T42: 1
B43: =B42+1 -> 14 | C43: *Is there data to characterize access to public clean air spaces, including by multiple transportation modes, e.g. sidewalks, roadways, public transit? | D43: 0 | J43: 1 | N43: 1 | R43: 1 | S43: 1
B44: =B43+1 -> 15 | C44: *Does your city collect health outcome data at high spatial and temporal resolution? For example, does it collect data on the number of daily visits to specific clinics or hospitals (and the causes for those visits), or the number of child absences from city schools? “High spatial resolution” means that you know the approximate location (residential address, address of medical facility, or neighborhood) of the health event. “High temporal resolution” means daily or, at a minimum, weekly counts, though yearly counts can still be helpful when modeling the impacts of air pollution policies over long periods of time. Note: this question only asks whether the city government collects this data directly. Separate questions later in the questionnaire will ask about data sharing with hospitals, ministries of health, and other groups that may have health data. | D44: 1.5 | H44: 1 | K44: 1 | N44: 1 | P44: 1 | R44: 1
B45: =B44+1 -> 16 | C45: Does your city track and make available data on competing risks to health and equity (e.g., drinking water quality, pesticide use, chemical exposures)? | D45: 1 | H45: 1 | O45: 1 | R45: 1
B46: =B45+1 -> 17 | C46: *Does your city collect labor market data (e.g., by gender, race/ethnicity, age, region, occupation) on current workforce composition, sectoral vulnerabilities related to air quality policies and energy transitions, and potential for participation in green job sectors? | D46: 1 | H46: 1 | P46: 1 | S46: 1
...

Sheet Scoring
H1: CB | I1: PS | J1: IM | K1: AP | L1: SE | M1: TC | N1: DI | O1: IP | P1: PE | Q1: DE | R1: SO | S1: AI
C3: EQuiPD: Equity in Air Quality Policy & Data Ecosystem
C4: Scoring
A5: EQuiPD | B5: ="EQuiPD Self-Assessment Scores: "&IF('Self-Assessment'!$D$23="Not listed",'Self-Assessment'!$D$24,'Self-Assessment'!$D$23)&" "&'Self-Assessment'!D$26 -> EQuiPD Self-Assessment Scores: United Arab Emirates - Dubai 11/26/2025 | G5: EQuiPD
A7: EQuiPD | B7: ="EQuiPD Self-Assessment Scores: "&IF('Self-Assessment'!$D$23="Not listed",'Self-Assessment'!$D$24,'Self-Assessment'!$D$23)&" "&'Self-Assessment'!D$26 -> EQuiPD Self-Assessment Scores: United Arab Emirates - Dubai 11/26/2025 | E7: View recommendations and next steps | G7: EQuiPD
B8: Data-sharing partnerships & management tools
B9: Robust capacity in data collection, analysis, and public transparency is essential for equitable air quality policies. This means systems that detect health and economic disparities, integrate diverse datasets, and map cumulative environmental burdens by community and socioeconomic status. Open access to data, strong local partnerships, and active involvement of marginalized communities in monitoring and decision-making help ensure that interventions are both effective and just. Regular, transparent reporting and evaluation of outcomes are crucial for accountability and ongoing policy improvement.
D10: Learn more about Categories, Domains, and Themes
C11: Equity Themes
B12: Domains | C12: Distributional Equity | D12: Socioeconomic Resilience and Opportunity | E12: Access and Inclusivity | F12: Overall
B13: Technical Capacity | C13: =IFERROR(AVERAGEIFS('Self-Assessment'!D$29:D$313,'Self-Assessment'!H$29:H$313,1,'Self-Assessment'!N$29:N$313,1,'Self-Assessment'!R$29:R$313,1),"") -> 0.4375 | D13: =IFERROR(AVERAGEIFS('Self-Assessment'!D$29:D$313,'Self-Assessment'!H$29:H$313,1,'Self-Assessment'!N$29:N$313,1,'Self-Assessment'!S$29:S$313,1),"") -> 0.5 | E13: =IFERROR(AVERAGEIFS('Self-Assessment'!D$29:D$313,'Self-Assessment'!H$29:H$313,1,'Self-Assessment'!N$29:N$313,1,'Self-Assessment'!T$29:T$313,1),"") -> 0.875 | F13: =IFERROR(AVERAGEIFS('Self-Assessment'!D$29:D$313,'Self-Assessment'!H$29:H$313,1,'Self-Assessment'!N$29:N$313,1),"") -> 0.61538462
B14: Data Integration | C14: =IFERROR(AVERAGEIFS('Self-Assessment'!D$29:D$313,'Self-Assessment'!H$29:H$313,1,'Self-Assessment'!O$29:O$313,1,'Self-Assessment'!R$29:R$313,1),"") -> 0.8 | D14: =IFERROR(AVERAGEIFS('Self-Assessment'!D$29:D$313,'Self-Assessment'!H$29:H$313,1,'Self-Assessment'!O$29:O$313,1,'Self-Assessment'!S$29:S$313,1),"") -> 0.5 | E14: =IFERROR(AVERAGEIFS('Self-Assessment'!D$29:D$313,'Self-Assessment'!H$29:H$313,1,'Self-Assessment'!O$29:O$313,1,'Self-Assessment'!T$29:T$313,1),"") -> 1 | F14: =IFERROR(AVERAGEIFS('Self-Assessment'!D$29:D$313,'Self-Assessment'!H$29:H$313,1,'Self-Assessment'!O$29:O$313,1),"") -> 0.71428571
B15: Internal Processes | C15: =IFERROR(AVERAGEIFS('Self-Assessment'!D$29:D$313,'Self-Assessment'!H$29:H$313,1,'Self-Assessment'!P$29:P$313,1,'Self-Assessment'!R$29:R$313,1),"") -> 1.1 | D15: =IFERROR(AVERAGEIFS('Self-Assessment'!D$29:D$313,'Self-Assessment'!H$29:H$313,1,'Self-Assessment'!P$29:P$313,1,'Self-Assessment'!S$29:S$313,1),"") -> 0.8 | E15: =IFERROR(AVERAGEIFS('Self-Assessment'!D$29:D$313,'Self-Assessment'!H$29:H$313,1,'Self-Assessment'!P$29:P$313,1,'Self-Assessment'!T$29:T$313,1),"") -> 0.91666667 | F15: =IFERROR(AVERAGEIFS('Self-Assessment'!D$29:D$313,'Self-Assessment'!H$29:H$313,1,'Self-Assessment'!P$29:P$313,1),"") -> 1
B16: Participation and Empowerment | C16: =IFERROR(AVERAGEIFS('Self-Assessment'!D$29:D$313,'Self-Assessment'!H$29:H$313,1,'Self-Assessment'!Q$29:Q$313,1,'Self-Assessment'!R$29:R$313,1),"") -> 0.33333333 | D16: =IFERROR(AVERAGEIFS('Self-Assessment'!D$29:D$313,'Self-Assessment'!H$29:H$313,1,'Self-Assessment'!Q$29:Q$313,1,'Self-Assessment'!S$29:S$313,1),"") -> 1 | E16: =IFERROR(AVERAGEIFS('Self-Assessment'!D$29:D$313,'Self-Assessment'!H$29:H$313,1,'Self-Assessment'!Q$29:Q$313,1,'Self-Assessment'!T$29:T$313,1),"") -> 0.42857143 | F16: =IFERROR(AVERAGEIFS('Self-Assessment'!D$29:D$313,'Self-Assessment'!H$29:H$313,1,'Self-Assessment'!Q$29:Q$313,1),"") -> 0.44444444
B17: Overall | C17: =IFERROR(AVERAGEIFS('Self-Assessment'!D$29:D$313,'Self-Assessment'!H$29:H$313,1,'Self-Assessment'!R$29:R$313,1),"") -> 0.75 | D17: =IFERROR(AVERAGEIFS('Self-Assessment'!D$29:D$313,'Self-Assessment'!H$29:H$313,1,'Self-Assessment'!S$29:S$313,1),"") -> 0.75 | E17: =IFERROR(AVERAGEIFS('Self-Assessment'!D$29:D$313,'Self-Assessment'!H$29:H$313,1,'Self-Assessment'!T$29:T$313,1),"") -> 0.78571429 | F17: =IFERROR(AVERAGEIFS('Self-Assessment'!D$29:D$313,'Self-Assessment'!H$29:H$313,1),"") -> 0.75925926
B19: City/institutional buy-in, capacity building & training
B20: Building and sustaining robust technical and organizational capacity is vital for equitable air quality policy-making. This involves having political buy-in to channel resources and mandate and accessible tools and trained staff to map, analyze, and communicate air quality gradients, their health and equity impacts, as well as resources for ongoing public and community training. Budgets and leadership structures must support long-term system upgrades, prioritize high-burden communities, and ensure regular, transparent evaluations—including independent audits and mechanisms for community input. Effective capacity also requires cross-sector coordination, sustained funding, and a commitment to policies that target disparity reduction and reflect the needs and diversity of the most affected populations.
C22: Equity Themes
B23: Domains | C23: Distributional Equity | D23: Socioeconomic Resilience and Opportunity | E23: Access and Inclusivity | F23: Overall
B24: Technical Capacity | C24: =IFERROR(AVERAGEIFS('Self-Assessment'!D$29:D$313,'Self-Assessment'!I$29:I$313,1,'Self-Assessment'!N$29:N$313,1,'Self-Assessment'!R$29:R$313,1),"") -> 0.25 | D24: =IFERROR(AVERAGEIFS('Self-Assessment'!D$29:D$313,'Self-Assessment'!I$29:I$313,1,'Self-Assessment'!N$29:N$313,1,'Self-Assessment'!S$29:S$313,1),"") -> 0 | E24: =IFERROR(AVERAGEIFS('Self-Assessment'!D$29:D$313,'Self-Assessment'!I$29:I$313,1,'Self-Assessment'!N$29:N$313,1,'Self-Assessment'!T$29:T$313,1),"") -> 0.66666667 | F24: =IFERROR(AVERAGEIFS('Self-Assessment'!D$29:D$313,'Self-Assessment'!I$29:I$313,1,'Self-Assessment'!N$29:N$313,1),"") -> 0.5
B25: Data Integration | C25: =IFERROR(AVERAGEIFS('Self-Assessment'!D$29:D$313,'Self-Assessment'!I$29:I$313,1,'Self-Assessment'!O$29:O$313,1,'Self-Assessment'!R$29:R$313,1),"") -> 0 | D25: =IFERROR(AVERAGEIFS('Self-Assessment'!D$29:D$313,'Self-Assessment'!I$29:I$313,1,'Self-Assessment'!O$29:O$313,1,'Self-Assessment'!S$29:S$313,1),"") -> 0 | E25: =IFERROR(AVERAGEIFS('Self-Assessment'!D$29:D$313,'Self-Assessment'!I$29:I$313,1,'Self-Assessment'!O$29:O$313,1,'Self-Assessment'!T$29:T$313,1),"") -> 0.25 | F25: =IFERROR(AVERAGEIFS('Self-Assessment'!D$29:D$313,'Self-Assessment'!I$29:I$313,1,'Self-Assessment'!O$29:O$313,1),"") -> 0.25
B26: Internal Processes | C26: =IFERROR(AVERAGEIFS('Self-Assessment'!D$29:D$313,'Self-Assessment'!I$29:I$313,1,'Self-Assessment'!P$29:P$313,1,'Self-Assessment'!R$29:R$313,1),"") -> 0.83333333 | D26: =IFERROR(AVERAGEIFS('Self-Assessment'!D$29:D$313,'Self-Assessment'!I$29:I$313,1,'Self-Assessment'!P$29:P$313,1,'Self-Assessment'!S$29:S$313,1),"") -> 0.33333333 | E26: =IFERROR(AVERAGEIFS('Self-Assessment'!D$29:D$313,'Self-Assessment'!I$29:I$313,1,'Self-Assessment'!P$29:P$313,1,'Self-Assessment'!T$29:T$313,1),"") -> 0.78571429 | F26: =IFERROR(AVERAGEIFS('Self-Assessment'!D$29:D$313,'Self-Assessment'!I$29:I$313,1,'Self-Assessment'!P$29:P$313,1),"") -> 0.9375
B27: Participation and Empowerment | C27: =IFERROR(AVERAGEIFS('Self-Assessment'!D$29:D$313,'Self-Assessment'!I$29:I$313,1,'Self-Assessment'!Q$29:Q$313,1,'Self-Assessment'!R$29:R$313,1),"") -> 1 | D27: =IFERROR(AVERAGEIFS('Self-Assessment'!D$29:D$313,'Self-Assessment'!I$29:I$313,1,'Self-Assessment'!Q$29:Q$313,1,'Self-Assessment'!S$29:S$313,1),"") -> 0.75 | E27: =IFERROR(AVERAGEIFS('Self-Assessment'!D$29:D$313,'Self-Assessment'!I$29:I$313,1,'Self-Assessment'!Q$29:Q$313,1,'Self-Assessment'!T$29:T$313,1),"") -> 0.25 | F27: =IFERROR(AVERAGEIFS('Self-Assessment'!D$29:D$313,'Self-Assessment'!I$29:I$313,1,'Self-Assessment'!Q$29:Q$313,1),"") -> 0.75
B28: Overall | C28: =IFERROR(AVERAGEIFS('Self-Assessment'!D$29:D$313,'Self-Assessment'!I$29:I$313,1,'Self-Assessment'!R$29:R$313,1),"") -> 0.66666667 | D28: =IFERROR(AVERAGEIFS('Self-Assessment'!D$29:D$313,'Self-Assessment'!I$29:I$313,1,'Self-Assessment'!S$29:S$313,1),"") -> 0.625 | E28: =IFERROR(AVERAGEIFS('Self-Assessment'!D$29:D$313,'Self-Assessment'!I$29:I$313,1,'Self-Assessment'!T$29:T$313,1),"") -> 0.625 | F28: =IFERROR(AVERAGEIFS('Self-Assessment'!D$29:D$313,'Self-Assessment'!I$29:I$313,1),"") -> 0.70588235
B30: ="EQuiPD Self-Assessment Scores: "&IF('Self-Assessment'!$D$23="Not listed",'Self-Assessment'!$D$24,'Self-Assessment'!$D$23)&" "&'Self-Assessment'!D$26 -> EQuiPD Self-Assessment Scores: United Arab Emirates - Dubai 11/26/2025
B31: Public support & engagement
B32: Ensuring that air quality policy-making addresses the diverse needs of all communities, especially the most vulnerable is critical to building public support & engagement. This means collecting and sharing data on access to clean air spaces, transportation, and public warnings, while tailoring resources and risk communications in multiple formats and languages. Economic impact assessments and compliance costs should explicitly analyze and address differential burdens, and feedback mechanisms must enable meaningful input from marginalized groups. Accessible and inclusive information about air pollution, impacts from policies and live tracking of changes over team can be game changing when it comes to building public support and addressing backlash. Sustained training, participatory processes, and investments in clean air monitoring infrastructure—combined with regular evaluation of health outcomes, public accountability, and integration of citizen data—ensure that policies are both effective and equitable for populations such as low-income, elderly, Indigenous, and minority residents.
C34: Equity Themes
B35: Domains | C35: Distributional Equity | D35: Socioeconomic Resilience and Opportunity | E35: Access and Inclusivity | F35: Overall
B36: Technical Capacity | C36: =IFERROR(AVERAGEIFS('Self-Assessment'!D$29:D$313,'Self-Assessment'!J$29:J$313,1,'Self-Assessment'!N$29:N$313,1,'Self-Assessment'!R$29:R$313,1),"") -> 0 | D36: =IFERROR(AVERAGEIFS('Self-Assessment'!D$29:D$313,'Self-Assessment'!J$29:J$313,1,'Self-Assessment'!N$29:N$313,1,'Self-Assessment'!S$29:S$313,1),"") -> 0.33333333 | E36: =IFERROR(AVERAGEIFS('Self-Assessment'!D$29:D$313,'Self-Assessment'!J$29:J$313,1,'Self-Assessment'!N$29:N$313,1,'Self-Assessment'!T$29:T$313,1),"") -> 0.66666667 | F36: =IFERROR(AVERAGEIFS('Self-Assessment'!D$29:D$313,'Self-Assessment'!J$29:J$313,1,'Self-Assessment'!N$29:N$313,1),"") -> 0.33333333
B37: Data Integration | C37: =IFERROR(AVERAGEIFS('Self-Assessment'!D$29:D$313,'Self-Assessment'!J$29:J$313,1,'Self-Assessment'!O$29:O$313,1,'Self-Assessment'!R$29:R$313,1),"") -> 1 | D37: =IFERROR(AVERAGEIFS('Self-Assessment'!D$29:D$313,'Self-Assessment'!J$29:J$313,1,'Self-Assessment'!O$29:O$313,1,'Self-Assessment'!S$29:S$313,1),"") -> 1 | E37: =IFERROR(AVERAGEIFS('Self-Assessment'!D$29:D$313,'Self-Assessment'!J$29:J$313,1,'Self-Assessment'!O$29:O$313,1,'Self-Assessment'!T$29:T$313,1),"") -> 0.7 | F37: =IFERROR(AVERAGEIFS('Self-Assessment'!D$29:D$313,'Self-Assessment'!J$29:J$313,1,'Self-Assessment'!O$29:O$313,1),"") -> 0.75
B38: Internal Processes | C38: =IFERROR(AVERAGEIFS('Self-Assessment'!D$29:D$313,'Self-Assessment'!J$29:J$313,1,'Self-Assessment'!P$29:P$313,1,'Self-Assessment'!R$29:R$313,1),"") -> 0.5 | D38: =IFERROR(AVERAGEIFS('Self-Assessment'!D$29:D$313,'Self-Assessment'!J$29:J$313,1,'Self-Assessment'!P$29:P$313,1,'Self-Assessment'!S$29:S$313,1),"") -> 0.75 | E38: =IFERROR(AVERAGEIFS('Self-Assessment'!D$29:D$313,'Self-Assessment'!J$29:J$313,1,'Self-Assessment'!P$29:P$313,1,'Self-Assessment'!T$29:T$313,1),"") -> 0.6 | F38: =IFERROR(AVERAGEIFS('Self-Assessment'!D$29:D$313,'Self-Assessment'!J$29:J$313,1,'Self-Assessment'!P$29:P$313,1),"") -> 0.57142857
B39: Participation and Empowerment | C39: =IFERROR(AVERAGEIFS('Self-Assessment'!D$29:D$313,'Self-Assessment'!J$29:J$313,1,'Self-Assessment'!Q$29:Q$313,1,'Self-Assessment'!R$29:R$313,1),"") -> 0.33333333 | D39: =IFERROR(AVERAGEIFS('Self-Assessment'!D$29:D$313,'Self-Assessment'!J$29:J$313,1,'Self-Assessment'!Q$29:Q$313,1,'Self-Assessment'!S$29:S$313,1),"") -> 1 | E39: =IFERROR(AVERAGEIFS('Self-Assessment'!D$29:D$313,'Self-Assessment'!J$29:J$313,1,'Self-Assessment'!Q$29:Q$313,1,'Self-Assessment'!T$29:T$313,1),"") -> 1 | F39: =IFERROR(AVERAGEIFS('Self-Assessment'!D$29:D$313,'Self-Assessment'!J$29:J$313,1,'Self-Assessment'!Q$29:Q$313,1),"") -> 0.6
B40: Overall | C40: =IFERROR(AVERAGEIFS('Self-Assessment'!D$29:D$313,'Self-Assessment'!J$29:J$313,1,'Self-Assessment'!R$29:R$313,1),"") -> 0.2 | D40: =IFERROR(AVERAGEIFS('Self-Assessment'!D$29:D$313,'Self-Assessment'!J$29:J$313,1,'Self-Assessment'!S$29:S$313,1),"") -> 0.6 | E40: =IFERROR(AVERAGEIFS('Self-Assessment'!D$29:D$313,'Self-Assessment'!J$29:J$313,1,'Self-Assessment'!T$29:T$313,1),"") -> 0.72222222 | F40: =IFERROR(AVERAGEIFS('Self-Assessment'!D$29:D$313,'Self-Assessment'!J$29:J$313,1),"") -> 0.53571429
B42: Health & economic impact modelling
B43: Equitable air quality policy-making relies on comprehensive, accurate modeling and monitoring systems that explicitly quantify health and economic impacts of particular policies for vulnerable and marginalized groups. This involves ensuring exposure and scenario-based models reflect real-world conditions through collaboration with monitoring networks, validation in data-sparse areas, and integration of fine-scale demographic and economic data. Analyses must be stratified by factors such as income, age, race, and geography, translating results into meaningful, accessible formats (e.g., public dashboards, maps, and plain-language summaries) that inform both policy and community resilience efforts. Ongoing community input, transparent communication of methods and limitations, and regular updates ensure that modeling truly supports fair distribution of benefits and burdens, strengthens preparedness, and provides targeted support to those most affected by air pollution and regulatory changes.
C45: Equity Themes
B46: Domains | C46: Distributional Equity | D46: Socioeconomic Resilience and Opportunity | E46: Access and Inclusivity | F46: Overall
B47: Technical Capacity | C47: =IFERROR(AVERAGEIFS('Self-Assessment'!D$29:D$313,'Self-Assessment'!K$29:K$313,1,'Self-Assessment'!N$29:N$313,1,'Self-Assessment'!R$29:R$313,1),"") -> 0.3125 | D47: =IFERROR(AVERAGEIFS('Self-Assessment'!D$29:D$313,'Self-Assessment'!K$29:K$313,1,'Self-Assessment'!N$29:N$313,1,'Self-Assessment'!S$29:S$313,1),"") -> 0 | E47: =IFERROR(AVERAGEIFS('Self-Assessment'!D$29:D$313,'Self-Assessment'!K$29:K$313,1,'Self-Assessment'!N$29:N$313,1,'Self-Assessment'!T$29:T$313,1),"") -> 0.2 | F47: =IFERROR(AVERAGEIFS('Self-Assessment'!D$29:D$313,'Self-Assessment'!K$29:K$313,1,'Self-Assessment'!N$29:N$313,1),"") -> 0.25
B48: Data Integration | C48: =IFERROR(AVERAGEIFS('Self-Assessment'!D$29:D$313,'Self-Assessment'!K$29:K$313,1,'Self-Assessment'!O$29:O$313,1,'Self-Assessment'!R$29:R$313,1),"") -> 0.1875 | D48: =IFERROR(AVERAGEIFS('Self-Assessment'!D$29:D$313,'Self-Assessment'!K$29:K$313,1,'Self-Assessment'!O$29:O$313,1,'Self-Assessment'!S$29:S$313,1),"") -> 0 | E48: =IFERROR(AVERAGEIFS('Self-Assessment'!D$29:D$313,'Self-Assessment'!K$29:K$313,1,'Self-Assessment'!O$29:O$313,1,'Self-Assessment'!T$29:T$313,1),"") -> 0.25 | F48: =IFERROR(AVERAGEIFS('Self-Assessment'!D$29:D$313,'Self-Assessment'!K$29:K$313,1,'Self-Assessment'!O$29:O$313,1),"") -> 0.17857143
...

Sheet Recommendations
A1: EQuiPD | B1: short_q | C1: Question | D1: Response | E1: Recommendations
A2: v112025
C3: EQuiPD: Equity in Air Quality Policy & Data Ecosystem
C4: Recommendations
C5: Recommendations
C6: To identify gaps and recommendations begin by filtering by category, domain, and/or equity theme. Use the dropdown arrows in the right-hand columns below and check '1' for the areas you are interested in learning more about. | H6: Categories | N6: Domains | R6: Themes
B7: 0 | C7: Data Collection | D7: Score | E7: Recommendations | H7: Data-sharing partnerships & management tools | I7: City/institutional buy-in, capacity building & training | J7: Public support & engagement | K7: Health & economic impact modeling | L7: Estimating air pollution | M7: Source & emission inventories | N7: Technical Capability | O7: Data Integration | P7: Internal processes | Q7: Participation and Empowerment | R7: Distributional Equity | S7: Socioeconomic Resilience and Opportunity | T7: Access and Inclusivity
B8: =B7+1 -> 1 | C8: *Do air pollution monitoring locations prioritize high-risk groups (for example., children, elderly, people with pre-existing conditions) and neighborhoods with historical underinvestment? | D8: ='Self-Assessment'!D30 -> 1 | E8: Develop a structured siting protocol that evaluates sensitive populations, land use, and pollution sources to ensure monitors are placed where health, social, economic inequities are highest. Examples: Install monitors near schools located by major roadways; add sensors in neighborhoods with high asthma hospitalization rates or high rates of joblessness or poverty. | L8: 1 | P8: 1 | R8: 1
B9: =B8+1 -> 2 | C9: Are community members from marginalized or vulnerable groups–or from disproportionately exposed areas of your city–engaged in decisionmaking about where to locate air pollution monitors? Marginalized community members may include low-income residents, racial or ethnic minority groups, migrants, linguistic minorities, religious minorities, Indigenous peoples, women, or any other oppressed or disenfranchised group. | D9: ='Self-Assessment'!D31 -> 1 | E9: Create a community advisory panel with real decision‑making power in monitor placement to ensure lived experience shapes data coverage. Examples: Allow residents to vote on final monitor placements in two high‑pollution corridors; rotate panel membership annually to include renters from impacted zones. | H9: 1 | L9: 1 | Q9: 1 | T9: 1
B10: =B9+1 -> 3 | C10: Are labor unions, worker cooperatives, and community organizations actively engaged in decisionmaking about where to locate air pollution monitors? Spatial and temporal resolution should be high enough to identify specific neighborhoods and other areas of your city that are disproportionately impacted by air pollution. | D10: ='Self-Assessment'!D32 -> 1 | E10: Include unions and community groups in siting workshops so occupational and local knowledge informs placement. Examples: Hold sessions with custodial worker unions to map indoor/outdoor hotspots; invite public housing tenant groups to identify overlooked pollution areas. | H10: 1 | L10: 1 | M10: 1 | Q10: 1 | S10: 1 | T10: 1
B11: =B10+1 -> 4 | C11: *Does your city collect air pollution data at high spatial and temporal resolution, especially in areas of concern and prioritize high risk groups (e.g., children, elderly, underinvested neighborhoods)? Spatial and temporal resolution should be high enough to identify specific neighborhoods and other areas of your city that are disproportionately impacted by air pollution. | D11: ='Self-Assessment'!D33 -> 1.5 | E11: Deploy more sensors in environmental justice neighborhoods where pollution varies block‑to‑block. Examples: Install sensors along heavy truck freight routes; add outdoor sensors around senior housing complexes affected by idling buses. | L11: 1 | N11: 1 | R11: 1
B12: =B11+1 -> 5 | C12: *Does your city collect air pollution data from point, area, and mobile sources, including power plants, shipping lanes, transportation hubs and routes, and industrial areas? | D12: ='Self-Assessment'!D34 -> 3 | E12: Integrate all major emissions inventories, including industrial, commercial, and mobile sources, into a unified city emissions tracking database. Examples: Merge port cargo handling equipment emissions with truck movement data; integrate airport ground operations emissions into citywide inventory. | M12: 1 | N12: 1 | R12: 1 | S12: 1
B13: =B12+1 -> 6 | C13: Are smaller, un-inventoried, unconventional, hyper-local, or illegal sources of air pollution tracked by your city, preferably in consultation with vulnerable communities? Such sources may include backyard burning or unlicensed chemical use. | D13: ='Self-Assessment'!D35 -> 1 | E13: Set up a reporting system where city residents can submit reports of emissions from small and unconventional sources that are often missed in inventories. Examples: Register generators used by food trucks; log emissions from small auto‑body shops using solvent‑based paints. | H13: 1 | J13: 1 | M13: 1 | O13: 1 | P13: 1 | Q13: 1 | R13: 1 | S13: 1
B14: =B13+1 -> 7 | C14: *Does your city collect detailed social, demographic, and economic data about its residents and where they live? These datasets might include resident age, sex and gender, income, migration status, county of origin, racial or ethnic identity, religious affiliation, primary language spoken, education level, employment status, and occupation. They might also include area-level variables like poverty rates or joblessness rates. This data is critical to understanding the sociodemographic composition of neighborhoods and how some groups might be affected by air pollution and air quality policies more than others. | D14: ='Self-Assessment'!D36 -> 1 | E14: Develop neighborhood- or block‑level demographic datasets to support granular equity analyses and pollutant‑exposure comparisons. Examples: Map block‑level renter density; compile household‑income distributions at sub‑neighborhood scales. | H14: 1 | J14: 1 | N14: 1 | P14: 1 | S14: 1 | T14: 1
B15: =B14+1 -> 8 | C15: Does your city government have partnerships with industry, transportation, and agricultural sectors to improve emission inventories? | D15: ='Self-Assessment'!D37 -> 3 | E15: Convene an emissions‑improvement working group with major sectors to update inventories annually. Examples: Meet quarterly with refinery operators to review flaring data; coordinate with warehouse operators to track truck fleet turnover. | M15: 1 | Q15: 1 | S15: 1
B16: =B15+1 -> 9 | C16: *Is data collected regarding the type of energy sources (coal, oil, gas, renewables, etc.) used by households in your city, as well as the location and number of such households? For example, do you know the location and number of households that have access to “clean energy,” which includes energy sources that produce no greenhouse gas emissions during their production or use? | D16: ='Self-Assessment'!D38 -> 1 | E16: Gather or estimate household fuel‑use patterns to identify indoor and outdoor emissions sources. Examples: Map homes still using wood stoves; identify multifamily buildings heated with older oil boilers. | H16: 1 | N16: 1 | S16: 1
B17: =B16+1 -> 10 | C17: Does your city have the ability (sensors, expertise, etc) to gather indoor air quality data across diverse housing types and locations (e.g., underinvested neighborhoods, high-rise apartments)? | D17: ='Self-Assessment'!D39 -> 1 | E17: Deploy portable indoor air sensors with partners such as housing authorities to understand indoor exposures. Examples: Place sensors in public‑housing units during winter heating season; monitor indoor PM2.5 in childcare centers near freeways. | L17: 1 | N17: 1 | T17: 1
B18: =B17+1 -> 11 | C18: Does your city collect data on indoor air quality proxy measures? “Proxy measures” include any data points that indicate potential indoor air quality problems. For example, mold complaints or mold abatement requests can indicate homes with poor indoor air quality. | D18: ='Self-Assessment'!D40 -> 0 | E18: Incorporate housing complaints and code enforcement requests as indicators of indoor air quality issues. Examples: Flag ventilation failure complaints; track mold reports as indicators of moisture‑driven air quality concerns. | L18: 1 | N18: 1 | T18: 1
B19: =B18+1 -> 12 | C19: *Does your city collect or have access to real-time meteorological forecast data for your city and the surrounding areas? Meteorological data can be important both for air quality monitoring and for alerting residents to potential health hazards. Such data is particularly important for cities that experience extreme weather events. | D19: ='Self-Assessment'!D41 -> 3 | E19: Integrate real‑time meteorological forecasts with pollution modeling for better short‑term predictions. Examples: Ingest hourly wind direction forecasts to predict smoke movement; apply inversion forecast data during winter stagnation periods; or simply record air temperature highs and lows alongside air quality data. | L19: 1 | N19: 1 | R19: 1
B20: =B19+1 -> 13 | C20: *Does your city collect data on accessibility that can characterize inequities for specific vulnerable populations, such as low-income or elderly populations? For this question, “accessibility” refers to whether all city residents–regardless of their physical or intellectual abilities–can interact with the information on air quality and related issues that you provide. | D20: ='Self-Assessment'!D42 -> 0 | E20: Conduct accessibility audits and study barriers that limit public access to air quality information. Examples: Survey speakers of non-native languages about website usability; analyze whether mobile users can navigate the dashboard easily. | J20: 1 | O20: 1 | T20: 1
B21: =B20+1 -> 14 | C21: *Is there data to characterize access to public clean air spaces, including by multiple transportation modes, e.g. sidewalks, roadways, public transit? | D21: ='Self-Assessment'!D43 -> 0 | E21: Map clean‑air shelters and measure their accessibility by transit and walking. Examples: Identify libraries with HEPA filtration; evaluate whether shelters near industrial zones have transit service after 20:00 (8:00pm). | J21: 1 | N21: 1 | R21: 1 | S21: 1
B22: =B21+1 -> 15 | C22: *Does your city collect health outcome data at high spatial and temporal resolution? For example, does it collect data on the number of daily visits to specific clinics or hospitals (and the causes for those visits), or the number of child absences from city schools? “High spatial resolution” means that you know the approximate location (residential address, address of medical facility, or neighborhood) of the health event. “High temporal resolution” means daily or, at a minimum, weekly counts, though yearly counts can still be helpful when modeling the impacts of air pollution policies over long periods of time. Note: this question only asks whether the city government collects this data directly. Separate questions later in the questionnaire will ask about data sharing with hospitals, ministries of health, and other groups that may have health data. | D22: ='Self-Assessment'!D44 -> 1.5 | E22: Create secure, geocoded feeds of de‑identified health data to track pollution‑related illnesses. Examples: Receive weekly asthma‑related ER visit counts by neighborhood; map clinic visits for COPD exacerbations. | H22: 1 | K22: 1 | N22: 1 | P22: 1 | R22: 1
B23: =B22+1 -> 16 | C23: Does your city track and make available data on competing risks to health and equity (e.g., drinking water quality, pesticide use, chemical exposures)? | D23: ='Self-Assessment'!D45 -> 1 | E23: Build an integrated hazard dashboard combining environmental, health, and exposure indicators. Examples: Show PM2.5 and ozone next to heat‑index alerts; visualize multi‑day wildfire smoke forecasts alongside hospital surge data. | H23: 1 | O23: 1 | R23: 1
B24: =B23+1 -> 17 | C24: *Does your city collect labor market data (e.g., by gender, race/ethnicity, age, region, occupation) on current workforce composition, sectoral vulnerabilities related to air quality policies and energy transitions, and potential for participation in green job sectors? | D24: ='Self-Assessment'!D46 -> 1 | E24: Acquire workforce and labor sector datasets to evaluate impacts of environmental policies on workers. Examples: Map diesel mechanic employment by racial or ethnic identity or country of origin; identify neighborhoods dependent on refinery‑related jobs. | H24: 1 | P24: 1 | S24: 1
B25: =B24+1 -> 18 | C25: Do you collect data on how air quality-related costs (such as energy or transportation expenses) affect households and businesses? | D25: ='Self-Assessment'!D47 -> 0 | E25: Track household energy and transportation burdens to understand economic stress linked to pollution and energy transitions. Examples: Analyze utility bill data for low‑income households; survey commute distances for car‑dependent neighborhoods. | K25: 1 | N25: 1 | S25: 1 | T25: 1
B26: =B25+1 -> 19 | C26: Are members of communities that are disproportionately impacted by air pollution engaged in the design and review of data systems that monitor labor market data and other job-related outcomes? For this question, “job-related” outcomes include opportunities to participate in job retraining, job placement, and green job creation programs. This is important because air quality policies may not be equitable if they result in economic hardship for vulnerable populations. Instead, equitable air quality policies should provide benefits to vulnerable populations, including economic and job-related benefits. | D26: ='Self-Assessment'!D48 -> 0 | E26: Hold co‑design workshops with workers and communities to shape labor data systems used in policy decisions. Examples: Host sessions with delivery drivers affected by zero emission zones; collaborate with warehouse workers on job quality indicators. | H26: 1 | Q26: 1 | T26: 1
B27: =B26+1 -> 20 | C27: Does your city collect data to track economic transitions related to air quality (e.g., shifts in employment, consumer prices, small business closures/openings)? | D27: ='Self-Assessment'!D49 -> 0 | E27: Monitor economic indicators linked to environmental transitions to anticipate job shifts or cost burdens. Examples: Track employment changes after electrifying port drayage; monitor small business costs related to new emissions standards. | K27: 1 | O27: 1 | S27: 1
B28: =B27+1 -> 21 | C28: *Does your city collect data on the combined impacts of air quality interventions on employment in economically disadvantaged communities? For example, are potential job losses or gains due to air quality interventions monitored? For this question, consider all types of “air quality interventions,”, including transitions to clean (or cleaner) energy, clean (or cleaner) transportation, clean (or cleaner) waste management systems, or any other policy or program meant to reduce air pollution. | D28: ='Self-Assessment'!D50 -> 0 | E28: Require job impact assessments for major clean air interventions to understand workforce consequences. Examples: Model job shifts from gas station closures; evaluate employment impacts of electrifying municipal fleets. | H28: 1 | N28: 1 | O28: 1 | S28: 1
B29: =B28+1 -> 22 | C29: *Does your city systematically keep track of and report data gaps (for example, missing or unavailable data) in its datasets that might disproportionately impact disadvantaged communities? For this question, “datasets” include all datasets relevant to equity analyses, such as data on health burdens, employment opportunities, economic activity, accessibility (e.g., transportation), etc. | D29: ='Self-Assessment'!D51 -> 0 | E29: Maintain a transparent registry documenting data gaps that hinder equity assessments. Examples: Note missing small business fuel use data; flag insufficient temporal coverage for neighborhood‑level PM2.5. | H29: 1 | J29: 1 | P29: 1 | Q29: 1 | T29: 1
B30: =B29+1 -> 23 | C30: Is there a mechanism (for example, regular meetings in neighborhoods across your city) to ensure that community-generated data and lived experiences are collected and used by city government staff for policy, resource allocation, and program design? | D30: ='Self-Assessment'!D52 -> 0 | E30: Create a platform for uploading community‑generated observations, sensor data, or complaints. Examples: Let residents submit odor events via a mobile app; allow upload of community low‑cost PM2.5 sensor data. | I30: 1 | O30: 1 | P30: 1 | Q30: 1 | R30: 1 | S30: 1 | T30: 1
B31: =B30+1 -> 24 | C31: *Does your city have systems for documentation and version control for all of its datasets? | D31: ='Self-Assessment'!D53 -> 0 | E31: Use version‑controlled repositories to store datasets, code, and metadata. Examples: Maintain emissions inventory scripts in GitHub; track model update history through tagged releases. | H31: 1 | I31: 1 | N31: 1 | P31: 1 | R31: 1 | S31: 1 | T31: 1
B32: =B31+1 -> 25 | C32: *Do air quality modeling staff collaborate with staff maintaining air quality monitoring networks so that they can bias-correct model predictions? | D32: ='Self-Assessment'!D54 -> 2 | E32: Hold regular coordination meetings between modeling and monitoring teams to align assumptions and calibration. Examples: Update modelers on new monitor calibration methods; inform monitoring teams about modeling parameter changes. | I32: 1 | K32: 1 | L32: 1 | P32: 1 | Q32: 1 | R32: 1
B34: =B32 -> 25 | C34: Data Partnerships and Linkages | D34: Score | E34: Recommendations | H34: 1 | I34: 1 | J34: 1 | K34: 1 | L34: 1 | M34: 1 | N34: 1 | O34: 1 | P34: 1 | Q34: 1 | R34: 1 | S34: 1 | T34: 1
B35: =B34+1 -> 26 | C35: *Does your city employ staff or consultants responsible for maintaining and linking air quality, environmental, demographic, health, economic, and other datasets and data pipelines? A “data pipeline” can include computing scripts–often in Python, R, or a similar language–that can make data available for analysis and sharing. | D35: ='Self-Assessment'!D57 -> 1 | E35: Assign a dedicated data engineering team to maintain pipelines and ensure data quality. Examples: Automate ingestion of real‑time sensor feeds; implement validation checks for emissions updates. | H35: 1 | I35: 1 | N35: 1 | R35: 1
B36: =B35+1 -> 27 | C36: *Has your city established data sharing partnerships between each department within your city that collects datasets that are important for analyzing the equity impacts of air quality policies? These departments in your city may include environmental and air quality departments, planning departments, health departments, transportation departments, and economic development or employment departments. Partnerships may take many forms, including regularly scheduled communication among departments, cross-department working groups, or data sharing agreements and Memorandums of Understanding. | D36: ='Self-Assessment'!D58 -> 1.5 | E36: Establish formal agreements between departments to standardize data sharing. Examples: Sign a Memorandum of Understanding (MOU) enabling health and environment departments to share de‑identified health data; formalize sharing of traffic data from transportation agencies. | H36: 1 | I36: 1 | P36: 1 | T36: 1
B37: =B36+1 -> 28 | C37: *Has your city established partnerships and processes to share air quality data with relevant officials in other levels of government, including state / provincial and national levels, that affect your city? Relevant officials may include those in ministries of health, public health, environment, transportation, economic development, infrastructure, and others. | D37: ='Self-Assessment'!D59 -> 2 | E37: Create standardized exports of air quality data to state-level or national authorities. Examples: Send monthly PM2.5 aggregates to the state air board; provide quarterly NO2 reports to national agencies. | H37: 1 | I37: 1 | P37: 1 | R37: 1 | T37: 1
B38: =B37+1 -> 29 | C38: *Has your city established partnerships and processes to share health and economic impact/disparities data with relevant officials in other levels of government, including state / provincial and national levels, that affect your city? Relevant officials may include those in ministries of health, public health, environment, transportation, economic development, infrastructure, and others. | D38: ='Self-Assessment'!D60 -> 1 | E38: Share health and environmental disparity data with higher-level (e.g., state or national) governments to support funding and policy alignment. Examples: Report racial disparities in asthma to national environmental protection ministries; share cumulative burden maps with national environmental justice offices (if any). | H38: 1 | I38: 1 | P38: 1 | R38: 1 | S38: 1 | T38: 1
B39: =B38+1 -> 30 | C39: Are satellite products linked with other air pollution monitoring data and with health and economic data (e.g., hospitalizations, asthma prevalence)? Satellite-derived air quality data can complement air quality monitoring data, particularly where monitoring data is sparse. | D39: ='Self-Assessment'!D61 -> 1.5 | E39: Use satellite‑based datasets to fill spatial gaps in monitoring coverage. Examples: Blend TROPOMI NO2 with ground monitors; use MODIS AOD to estimate PM2.5 in rural outskirts. | K39: 1 | L39: 1 | O39: 1 | R39: 1
B40: =B39+1 -> 31 | C40: *Does your city have the capacity to link air pollution model data (versus monitor data), particularly where either regulatory or low-cost air pollution monitor data is sparse? Air pollution model data (rather than monitor-based data) are often produced by outside experts. Thus, model-based data often needs to be linked. This question asks whether your city has the capacity to link this type of data. | D40: ='Self-Assessment'!D62 -> 1.5 | E40: Use modeled estimates when monitors are sparse or absent. Examples: Use CMAQ for industrial zones without sensors; apply WRF‑Chem for wildfire‑smoke scenarios. | L40: 1 | N40: 1 | R40: 1
B41: =B40+1 -> 32 | C41: Does the city or sponsor have access to long-term air quality monitoring data from national or state / provincial governments? By “long-term,” this question refers to data collected over several years. Ideally, this data will be at high spatial and temporal (e.g., daily) resolution as well. | D41: ='Self-Assessment'!D63 -> 2 | E41: Import multi‑year regional datasets to strengthen long‑term analyses. Examples: Incorporate a decade of ozone data from state networks; use 15 years of PM2.5 trends from national sites. | L41: 1 | N41: 1 | R41: 1
...

Sheet Definitions
C3: EQuiPD: Equity in Air Quality Policy & Data Ecosystem
C4: Definitions
C6: Categories
C7: Data-sharing partnerships & management tools
C8: Robust capacity in data collection, analysis, and public transparency is essential for equitable air quality policies. This means systems that detect health and economic disparities, integrate diverse datasets, and map cumulative environmental burdens by community and socioeconomic status. Open access to data, strong local partnerships, and active involvement of marginalized communities in monitoring and decision-making help ensure that interventions are both effective and just. Regular, transparent reporting and evaluation of outcomes are crucial for accountability and ongoing policy improvement.
C10: City/institutional buy-in, capacity building & training
C11: Building and sustaining robust technical and organizational capacity is vital for equitable air quality policy-making. This involves having political buy-in to channel resources and mandate and accessible tools and trained staff to map, analyze, and communicate air quality gradients, their health and equity impacts, as well as resources for ongoing public and community training. Budgets and leadership structures must support long-term system upgrades, prioritize high-burden communities, and ensure regular, transparent evaluations—including independent audits and mechanisms for community input. Effective capacity also requires cross-sector coordination, sustained funding, and a commitment to policies that target disparity reduction and reflect the needs and diversity of the most affected populations.
C13: Public support & engagement
C14: Ensuring that air quality policy-making addresses the diverse needs of all communities, especially the most vulnerable is critical to building public support & engagement. This means collecting and sharing data on access to clean air spaces, transportation, and public warnings, while tailoring resources and risk communications in multiple formats and languages. Economic impact assessments and compliance costs should explicitly analyze and address differential burdens, and feedback mechanisms must enable meaningful input from marginalized groups. Accessible and inclusive information about air pollution, impacts from policies and live tracking of changes over team can be game changing when it comes to building public support and addressing backlash. Sustained training, participatory processes, and investments in clean air monitoring infrastructure—combined with regular evaluation of health outcomes, public accountability, and integration of citizen data—ensure that policies are both effective and equitable for populations such as low-income, elderly, Indigenous, and minority residents.
C16: Health & economic impact modeling
C17: Equitable air quality policy-making relies on comprehensive, accurate modeling and monitoring systems that explicitly quantify health and economic impacts of particular policies for vulnerable and marginalized groups. This involves ensuring exposure and scenario-based models reflect real-world conditions through collaboration with monitoring networks, validation in data-sparse areas, and integration of fine-scale demographic and economic data. Analyses must be stratified by factors such as income, age, race, and geography, translating results into meaningful, accessible formats (e.g., public dashboards, maps, and plain-language summaries) that inform both policy and community resilience efforts. Ongoing community input, transparent communication of methods and limitations, and regular updates ensure that modeling truly supports fair distribution of benefits and burdens, strengthens preparedness, and provides targeted support to those most affected by air pollution and regulatory changes.
C19: Estimating air pollution
... C41: Ensuring equitable outcomes along the five equity impact areas outlined by C40. This theme addresses equitable access to information, services, public resources, infrastructure, participation in decision-making, and physical environments for all communities, especially those historically marginalized. Questions focus on accessibility and inclusion to services, public spaces, and information as well as engagement and decision making around data.

Sheet c40_cities
A1: City | B1: Country | C1: Combined
A2: Buenos Aires | B2: Argentina | C2: =B2&" - "&A2 -> Argentina - Buenos Aires
A3: Melbourne | B3: Australia | C3: =B3&" - "&A3 -> Australia - Melbourne
A4: Sydney | B4: Australia | C4: =B4&" - "&A4 -> Australia - Sydney
A5: Dhaka (North & South) | B5: Bangladesh | C5: =B5&" - "&A5 -> Bangladesh - Dhaka (North & South)
A6: Curitiba | B6: Brazil | C6: =B6&" - "&A6 -> Brazil - Curitiba
A7: Fortaleza | B7: Brazil | C7: =B7&" - "&A7 -> Brazil - Fortaleza
A8: Rio de Janeiro | B8: Brazil | C8: =B8&" - "&A8 -> Brazil - Rio de Janeiro
A9: Salvador | B9: Brazil | C9: =B9&" - "&A9 -> Brazil - Salvador
A10: São Paulo | B10: Brazil | C10: =B10&" - "&A10 -> Brazil - São Paulo
A11: Montréal | B11: Canada | C11: =B11&" - "&A11 -> Canada - Montréal
A12: Toronto | B12: Canada | C12: =B12&" - "&A12 -> Canada - Toronto
A13: Vancouver | B13: Canada | C13: =B13&" - "&A13 -> Canada - Vancouver
... A98: Ho Chi Minh City | B98: Vietnam | C98: =B98&" - "&A98 -> Vietnam - Ho Chi Minh City
C99: Not listed

Sheet org_detail
A1: Abbreviation | B1: Full_Name | C1: Organization
A2: DS | B2: Data-sharing partnerships & management tools | C2: Category
A3: CB | B3: City/institutional buy-in, capacity building & training | C3: Category
A4: PS | B4: Public support & engagement | C4: Category
A5: IM | B5: Health and economic impact modelling | C5: Category
A6: AP | B6: Estimating air pollution | C6: Category
A7: SE | B7: Source & emission inventories | C7: Category
A8: TC | B8: Technical Capacity | C8: Domain
A9: DI | B9: Data Integration | C9: Domain
A10: IP | B10: Internal Processes | C10: Domain
A11: PE | B11: Participation and Empowerment | C11: Domain
A12: DE | B12: Distributional Equity | C12: Equity Theme
... A14: AI | B14: Access and Inclusivity | C14: Equity Theme

Sheet QCount
A1: EQuiPD | F1: EQuiPD
B2: This page counts the number of questions at the intersection of each category, domain, and equity theme. Areas with fewer questions may be areas of opportunity to further expand or consider revising scoring mapping.
B4: Data-sharing partnerships & management tools
C6: Equity Themes
B7: Domains | C7: Distributional Equity | D7: Socioeconomic Resilience and Opportunity | E7: Access and Inclusivity
B8: Technical Capacity | C8: =IFERROR(COUNTIFS('Self-Assessment'!H$29:H$313,1,'Self-Assessment'!N$29:N$313,1,'Self-Assessment'!R$29:R$313,1),"") -> 8 | D8: =IFERROR(COUNTIFS('Self-Assessment'!H$29:H$313,1,'Self-Assessment'!N$29:N$313,1,'Self-Assessment'!S$29:S$313,1),"") -> 4 | E8: =IFERROR(COUNTIFS('Self-Assessment'!H$29:H$313,1,'Self-Assessment'!N$29:N$313,1,'Self-Assessment'!T$29:T$313,1),"") -> 4
B9: Data Integration | C9: =IFERROR(COUNTIFS('Self-Assessment'!H$29:H$313,1,'Self-Assessment'!O$29:O$313,1,'Self-Assessment'!R$29:R$313,1),"") -> 5 | D9: =IFERROR(COUNTIFS('Self-Assessment'!H$29:H$313,1,'Self-Assessment'!O$29:O$313,1,'Self-Assessment'!S$29:S$313,1),"") -> 2 | E9: =IFERROR(COUNTIFS('Self-Assessment'!H$29:H$313,1,'Self-Assessment'!O$29:O$313,1,'Self-Assessment'!T$29:T$313,1),"") -> 1
B10: Internal Processes | C10: =IFERROR(COUNTIFS('Self-Assessment'!H$29:H$313,1,'Self-Assessment'!P$29:P$313,1,'Self-Assessment'!R$29:R$313,1),"") -> 5 | D10: =IFERROR(COUNTIFS('Self-Assessment'!H$29:H$313,1,'Self-Assessment'!P$29:P$313,1,'Self-Assessment'!S$29:S$313,1),"") -> 5 | E10: =IFERROR(COUNTIFS('Self-Assessment'!H$29:H$313,1,'Self-Assessment'!P$29:P$313,1,'Self-Assessment'!T$29:T$313,1),"") -> 6
B11: Participation and Empowerment | C11: =IFERROR(COUNTIFS('Self-Assessment'!H$29:H$313,1,'Self-Assessment'!Q$29:Q$313,1,'Self-Assessment'!R$29:R$313,1),"") -> 3 | D11: =IFERROR(COUNTIFS('Self-Assessment'!H$29:H$313,1,'Self-Assessment'!Q$29:Q$313,1,'Self-Assessment'!S$29:S$313,1),"") -> 2 | E11: =IFERROR(COUNTIFS('Self-Assessment'!H$29:H$313,1,'Self-Assessment'!Q$29:Q$313,1,'Self-Assessment'!T$29:T$313,1),"") -> 7
B13: City/institutional buy-in, capacity building & training
C15: Equity Themes
B16: Domains | C16: Distributional Equity | D16: Socioeconomic Resilience and Opportunity | E16: Access and Inclusivity
B17: Technical Capacity | C17: =IFERROR(COUNTIFS('Self-Assessment'!I$29:I$313,1,'Self-Assessment'!N$29:N$313,1,'Self-Assessment'!R$29:R$313,1),"") -> 4 | D17: =IFERROR(COUNTIFS('Self-Assessment'!I$29:I$313,1,'Self-Assessment'!N$29:N$313,1,'Self-Assessment'!S$29:S$313,1),"") -> 1 | E17: =IFERROR(COUNTIFS('Self-Assessment'!I$29:I$313,1,'Self-Assessment'!N$29:N$313,1,'Self-Assessment'!T$29:T$313,1),"") -> 3
B18: Data Integration | C18: =IFERROR(COUNTIFS('Self-Assessment'!I$29:I$313,1,'Self-Assessment'!O$29:O$313,1,'Self-Assessment'!R$29:R$313,1),"") -> 2 | D18: =IFERROR(COUNTIFS('Self-Assessment'!I$29:I$313,1,'Self-Assessment'!O$29:O$313,1,'Self-Assessment'!S$29:S$313,1),"") -> 1 | E18: =IFERROR(COUNTIFS('Self-Assessment'!I$29:I$313,1,'Self-Assessment'!O$29:O$313,1,'Self-Assessment'!T$29:T$313,1),"") -> 4
B19: Internal Processes | C19: =IFERROR(COUNTIFS('Self-Assessment'!I$29:I$313,1,'Self-Assessment'!P$29:P$313,1,'Self-Assessment'!R$29:R$313,1),"") -> 6 | D19: =IFERROR(COUNTIFS('Self-Assessment'!I$29:I$313,1,'Self-Assessment'!P$29:P$313,1,'Self-Assessment'!S$29:S$313,1),"") -> 3 | E19: =IFERROR(COUNTIFS('Self-Assessment'!I$29:I$313,1,'Self-Assessment'!P$29:P$313,1,'Self-Assessment'!T$29:T$313,1),"") -> 7
B20: Participation and Empowerment | C20: =IFERROR(COUNTIFS('Self-Assessment'!I$29:I$313,1,'Self-Assessment'!Q$29:Q$313,1,'Self-Assessment'!R$29:R$313,1),"") -> 2 | D20: =IFERROR(COUNTIFS('Self-Assessment'!I$29:I$313,1,'Self-Assessment'!Q$29:Q$313,1,'Self-Assessment'!S$29:S$313,1),"") -> 2 | E20: =IFERROR(COUNTIFS('Self-Assessment'!I$29:I$313,1,'Self-Assessment'!Q$29:Q$313,1,'Self-Assessment'!T$29:T$313,1),"") -> 4
B22: Public support & engagement
C24: Equity Themes
B25: Domains | C25: Distributional Equity | D25: Socioeconomic Resilience and Opportunity | E25: Access and Inclusivity
